output/08.txt
time symbol vwap
8:00:00 A 73.35
8:00:00 AA 53.26
8:00:00 AABA 78.29
8:00:00 AAL 52.68
8:00:00 AAN 41.99
8:00:00 AAOI 32.99
8:00:00 AAP 117.84
8:00:00 AAPL 165.61
8:00:00 AAT 34.86
8:00:00 AAWW 57.03
8:00:00 AAXJ 81.19
8:00:00 AAXN 27.31
8:00:00 ABAX 74.18
8:00:00 ABB 27.92
8:00:00 ABBV 116.65
8:00:00 ABC 103.18
8:00:00 ABCB 54.75
8:00:00 ABCD 7.1
8:00:00 ABDC 8.0
8:00:00 ABEO 15.48
8:00:00 ABEV 6.84
8:00:00 ABG 74.09
8:00:00 ABLX 53.99
8:00:00 ABM 38.37
8:00:00 ABMD 234.65
8:00:00 ABR 8.26
8:00:00 ABR-A 25.35
8:00:00 ABT 62.48
8:00:00 ABTX 40.73
8:00:00 ABUS 5.23
8:00:00 ABX 14.22
8:00:00 AC 34.78
8:00:00 ACAD 30.79
8:00:00 ACBI 17.48
8:00:00 ACC 38.33
8:00:00 ACCO 12.02
8:00:00 ACET 11.49
8:00:00 ACGL 91.47
8:00:00 ACGLO 24.33
8:00:00 ACGLP 23.15
8:00:00 ACH 17.48
8:00:00 ACHC 34.34
8:00:00 ACHN 2.74
8:00:00 ACIA 35.3
8:00:00 ACIU 13.28
8:00:00 ACIW 22.99
8:00:00 ACLS 26.6
8:00:00 ACM 39.21
8:00:00 ACMR 5.32
8:00:00 ACN 160.39
8:00:00 ACOR 26.55
8:00:00 ACP 14.39
8:00:00 ACRE 12.79
8:00:00 ACRS 22.59
8:00:00 ACST 1.15
8:00:00 ACTA 15.55
8:00:00 ACU 24.0
8:00:00 ACV 22.23
8:00:00 ACWI 76.08
8:00:00 ACWV 86.97
8:00:00 ACWX 52.62
8:00:00 ACXM 27.47
8:00:00 ADAP 8.99
8:00:00 ADBE 196.89
8:00:00 ADC 47.8
8:00:00 ADES 8.16
8:00:00 ADI 91.91
8:00:00 ADM 42.72
8:00:00 ADMP 3.68
8:00:00 ADMS 39.51
8:00:00 ADNT 65.66
8:00:00 ADOM 1.65
8:00:00 ADP 120.78
8:00:00 ADRE 47.47
8:00:00 ADRO 6.65
8:00:00 ADS 255.74
8:00:00 ADSK 114.95
8:00:00 ADSW 24.29
8:00:00 ADT 12.18
8:00:00 ADTN 16.1
8:00:00 ADUS 35.9
8:00:00 ADVM 7.98
8:00:00 ADXS 3.01
8:00:00 AE 45.55
8:00:00 AEE 56.08
8:00:00 AEG 6.88
8:00:00 AEGN 25.21
8:00:00 AEHR 2.6
8:00:00 AEIS 73.02
8:00:00 AEL 34.12
8:00:00 AEM 47.16
8:00:00 AEMD 1.59
8:00:00 AEO 18.24
8:00:00 AEP 68.6
8:00:00 AER 54.34
8:00:00 AERI 56.84
8:00:00 AES 11.68
8:00:00 AET 189.04
8:00:00 AEZS 2.25
8:00:00 AFAM 58.49
8:00:00 AFG 113.44
8:00:00 AFI 15.86
8:00:00 AFK 26.13
8:00:00 AFL 88.77
8:00:00 AFSI 12.95
8:00:00 AFSI-A 18.61
8:00:00 AG 6.06
8:00:00 AGCO 72.55
8:00:00 AGEN 3.63
8:00:00 AGFSW 0.49
8:00:00 AGG 107.99
8:00:00 AGI 5.96
8:00:00 AGIO 80.88
8:00:00 AGLE 6.75
8:00:00 AGM 80.89
8:00:00 AGN 184.34
8:00:00 AGN-A 660.29
8:00:00 AGNC 19.05
8:00:00 AGNCB 25.67
8:00:00 AGNCN 25.12
8:00:00 AGO 35.74
8:00:00 AGR 48.18
8:00:00 AGRO 9.82
8:00:00 AGRX 3.3
8:00:00 AGS 18.99
8:00:00 AGYS 12.14
8:00:00 AHGP 28.78
8:00:00 AHH 14.29
8:00:00 AHL 37.85
8:00:00 AHL-C 25.92
8:00:00 AHP 9.28
8:00:00 AHPAW 0.48
8:00:00 AHT 6.42
8:00:00 AI 10.76
8:00:00 AIA 70.81
8:00:00 AIEQ 27.49
8:00:00 AIG 63.31
8:00:00 AIG+ 21.37
8:00:00 AIMC 52.95
8:00:00 AIMT 35.8
8:00:00 AINV 5.72
8:00:00 AIR 39.97
8:00:00 AIRG 10.22
8:00:00 AIT 74.23
8:00:00 AIV 41.26
8:00:00 AIZ 92.72
8:00:00 AJG 69.7
8:00:00 AJRD 27.61
8:00:00 AJX 13.71
8:00:00 AKAM 66.58
8:00:00 AKAO 12.56
8:00:00 AKBA 15.19
8:00:00 AKCA 23.35
8:00:00 AKER 0.25
8:00:00 AKO.B 28.81
8:00:00 AKR 24.48
8:00:00 AKRX 32.3
8:00:00 AKS 5.48
8:00:00 AKTS 5.81
8:00:00 AKTX 2.98
8:00:00 AL 48.78
8:00:00 ALB 111.53
8:00:00 ALBO 36.86
8:00:00 ALDR 14.41
8:00:00 ALE 71.84
8:00:00 ALEX 26.94
8:00:00 ALGN 267.11
8:00:00 ALGT 157.75
8:00:00 ALJJ 3.27
8:00:00 ALK 64.09
8:00:00 ALKS 58.27
8:00:00 ALL 98.91
8:00:00 ALLE 86.01
8:00:00 ALLT 4.92
8:00:00 ALLY 31.04
8:00:00 ALLY-A 25.95
8:00:00 ALNA 8.98
8:00:00 ALNY 131.38
8:00:00 ALOG 83.75
8:00:00 ALRM 37.62
8:00:00 ALRN 9.35
8:00:00 ALSK 2.18
8:00:00 ALT 1.86
8:00:00 ALTR 25.65
8:00:00 ALV 149.47
8:00:00 ALX 361.05
8:00:00 ALXN 123.27
8:00:00 AM 31.01
8:00:00 AMAG 14.6
8:00:00 AMAT 53.38
8:00:00 AMBA 50.13
8:00:00 AMBC 16.29
8:00:00 AMC 12.55
8:00:00 AMCN 1.21
8:00:00 AMCX 52.76
8:00:00 AMD 12.84
8:00:00 AME 76.78
8:00:00 AMED 54.13
8:00:00 AMEH 19.77
8:00:00 AMG 205.9
8:00:00 AMGN 191.4
8:00:00 AMGP 21.19
8:00:00 AMH 20.1
8:00:00 AMJ 29.28
8:00:00 AMKR 10.11
8:00:00 AMLP 11.47
8:00:00 AMN 53.7
8:00:00 AMNB 37.84
8:00:00 AMOT 34.73
8:00:00 AMP 172.64
8:00:00 AMPE 2.91
8:00:00 AMPH 19.06
8:00:00 AMRB 15.36
8:00:00 AMRC 8.8
8:00:00 AMRHW 0.68
8:00:00 AMRN 3.81
8:00:00 AMRS 5.0
8:00:00 AMSC 5.17
8:00:00 AMSF 61.35
8:00:00 AMT 144.85
8:00:00 AMTD 55.68
8:00:00 AMWD 135.69
8:00:00 AMX 18.5
8:00:00 AMZA 8.6
8:00:00 AMZN 1422.24
8:00:00 AN 60.43
8:00:00 ANAB 107.29
8:00:00 ANAT 127.38
8:00:00 ANCX 28.79
8:00:00 ANDE 34.4
8:00:00 ANDV 108.6
8:00:00 ANDX 51.76
8:00:00 ANET 274.62
8:00:00 ANF 21.09
8:00:00 ANFI 4.14
8:00:00 ANGI 13.54
8:00:00 ANGL 30.16
8:00:00 ANGO 17.12
8:00:00 ANH 4.97
8:00:00 ANIK 68.14
8:00:00 ANIP 67.55
8:00:00 ANSS 161.71
8:00:00 ANTM 242.91
8:00:00 ANW 4.72
8:00:00 ANY 2.35
8:00:00 AOBC 12.0
8:00:00 AON 141.43
8:00:00 AOS 66.47
8:00:00 AOSL 16.85
8:00:00 AP 14.05
8:00:00 APA 44.47
8:00:00 APAM 39.75
8:00:00 APC 59.75
8:00:00 APD 167.21
8:00:00 APEI 25.3
8:00:00 APH 92.75
8:00:00 APHB 1.2
8:00:00 APLE 19.5
8:00:00 APLP 13.59
8:00:00 APLS 17.37
8:00:00 APO 35.44
8:00:00 APOG 46.09
8:00:00 APOP 8.51
8:00:00 APPN 30.16
8:00:00 APPS 2.04
8:00:00 APRI 2.44
8:00:00 APRN 3.05
8:00:00 APTI 25.48
8:00:00 APTO 3.01
8:00:00 APTS 16.68
8:00:00 APTV 94.47
8:00:00 APU 47.16
8:00:00 APVO 3.44
8:00:00 AQ 12.96
8:00:00 AQB 2.7
8:00:00 AQN 10.74
8:00:00 AQUA 23.28
8:00:00 AQXP 13.0
8:00:00 AR 19.34
8:00:00 ARA 18.99
8:00:00 ARAY 5.59
8:00:00 ARC 2.43
8:00:00 ARCB 35.94
8:00:00 ARCC 16.06
8:00:00 ARCH 91.23
8:00:00 ARCT 8.3
8:00:00 ARCW 2.1
8:00:00 ARD 20.01
8:00:00 ARDC 16.17
8:00:00 ARDM 1.51
8:00:00 ARE 125.43
8:00:00 AREX 3.29
8:00:00 ARGS 2.32
8:00:00 ARGT 37.49
8:00:00 ARGX 79.19
8:00:00 ARI 18.35
8:00:00 ARII 39.24
8:00:00 ARKK 41.64
8:00:00 ARLP 20.58
8:00:00 ARLZ 1.71
8:00:00 ARMK 45.3
8:00:00 ARMO 30.1
8:00:00 ARNA 36.94
8:00:00 ARNC 29.86
8:00:00 AROC 9.6
8:00:00 AROW 33.25
8:00:00 ARR 23.85
8:00:00 ARRS 25.17
8:00:00 ARRY 14.44
8:00:00 ARTNA 37.39
8:00:00 ARW 82.11
8:00:00 ARWR 6.14
8:00:00 ASA 11.45
8:00:00 ASB 25.06
8:00:00 ASC 7.2
8:00:00 ASCMA 9.98
8:00:00 ASGN 68.71
8:00:00 ASH 74.12
8:00:00 ASHR 33.58
8:00:00 ASIX 40.29
8:00:00 ASMB 49.19
8:00:00 ASML 201.21
8:00:00 ASNA 2.14
8:00:00 ASND 52.21
8:00:00 ASNS 13.7
8:00:00 ASPS 30.43
8:00:00 ASPU 8.17
8:00:00 ASR 194.16
8:00:00 ASRV 4.2
8:00:00 ASTE 62.97
8:00:00 ASUR 15.0
8:00:00 ASX 7.16
8:00:00 ATAX 6.12
8:00:00 ATEN 7.04
8:00:00 ATGE 45.78
8:00:00 ATH 50.18
8:00:00 ATHM 81.82
8:00:00 ATHN 129.25
8:00:00 ATHX 1.8
8:00:00 ATI 27.87
8:00:00 ATKR 23.87
8:00:00 ATNI 59.56
8:00:00 ATNM 0.71
8:00:00 ATNX 14.96
8:00:00 ATO 82.79
8:00:00 ATOM 4.4
8:00:00 ATOS 0.53
8:00:00 ATR 87.55
8:00:00 ATRA 38.73
8:00:00 ATRC 16.78
8:00:00 ATRO 45.34
8:00:00 ATRS 2.26
8:00:00 ATSG 24.66
8:00:00 ATU 24.98
8:00:00 ATUS 21.75
8:00:00 ATVI 71.37
8:00:00 AU 11.05
8:00:00 AUDC 7.76
8:00:00 AUO 4.82
8:00:00 AUPH 5.46
8:00:00 AUTO 8.29
8:00:00 AUY 3.39
8:00:00 AVA 51.02
8:00:00 AVAV 51.58
8:00:00 AVB 167.7
8:00:00 AVDL 11.18
8:00:00 AVEO 3.03
8:00:00 AVGO 240.93
8:00:00 AVID 5.42
8:00:00 AVIR 0.59
8:00:00 AVK 16.24
8:00:00 AVP 2.48
8:00:00 AVT 42.84
8:00:00 AVXS 121.65
8:00:00 AVY 117.89
8:00:00 AWF 12.44
8:00:00 AWI 63.36
8:00:00 AWK 83.23
8:00:00 AWP 6.54
8:00:00 AWR 55.58
8:00:00 AXAS 2.33
8:00:00 AXDX 28.56
8:00:00 AXE 84.29
8:00:00 AXGN 27.35
8:00:00 AXL 17.97
8:00:00 AXON 2.04
8:00:00 AXP 99.38
8:00:00 AXS 50.63
8:00:00 AXSM 2.72
8:00:00 AXTA 31.25
8:00:00 AXTI 8.07
8:00:00 AXU 1.54
8:00:00 AYI 159.77
8:00:00 AYX 29.36
8:00:00 AZN 35.73
8:00:00 AZO 777.68
8:00:00 AZPN 78.59
8:00:00 AZRX 3.54
8:00:00 AZUL 28.92
8:00:00 B 66.05
8:00:00 BA 336.34
8:00:00 BABA 199.56
8:00:00 BABY 31.46
8:00:00 BAC 31.95
8:00:00 BAC+B 3.42
8:00:00 BAC-E 23.8
8:00:00 BAC-L 1253.29
8:00:00 BAC-W 26.16
8:00:00 BAK 31.49
8:00:00 BAL 51.34
8:00:00 BAM 40.83
8:00:00 BANC 19.42
8:00:00 BANR 54.33
8:00:00 BAP 236.22
8:00:00 BAS 19.43
8:00:00 BASI 2.08
8:00:00 BATRA 23.85
8:00:00 BAX 71.67
8:00:00 BB 12.6
8:00:00 BBBY 22.61
8:00:00 BBD 12.42
8:00:00 BBG 4.95
8:00:00 BBL 44.24
8:00:00 BBN 21.96
8:00:00 BBOX 3.66
8:00:00 BBRG 3.35
8:00:00 BBSI 70.59
8:00:00 BBT 55.44
8:00:00 BBT-E 24.77
8:00:00 BBU 38.69
8:00:00 BBVA 9.38
8:00:00 BBY 75.87
8:00:00 BC 62.96
8:00:00 BCE 46.56
