output/09.txt
time symbol vwap
9:00:00 A 73.2
9:00:00 AA 53.09
9:00:00 AABA 78.35
9:00:00 AAL 52.61
9:00:00 AAN 42.05
9:00:00 AAOI 32.86
9:00:00 AAON 35.95
9:00:00 AAP 118.88
9:00:00 AAPL 166.3
9:00:00 AAT 34.84
9:00:00 AAU 0.87
9:00:00 AAV 3.32
9:00:00 AAWW 56.74
9:00:00 AAXJ 81.3
9:00:00 AAXN 27.32
9:00:00 AB 27.45
9:00:00 ABAX 74.09
9:00:00 ABB 28.0
9:00:00 ABBV 116.51
9:00:00 ABC 103.11
9:00:00 ABCB 55.25
9:00:00 ABCD 7.1
9:00:00 ABEO 15.59
9:00:00 ABEV 6.83
9:00:00 ABLX 54.05
9:00:00 ABM 38.29
9:00:00 ABMD 234.81
9:00:00 ABR 8.24
9:00:00 ABT 62.46
9:00:00 ABTX 40.62
9:00:00 ABUS 5.18
9:00:00 ABX 14.24
9:00:00 AC 34.9
9:00:00 ACAD 30.85
9:00:00 ACBI 17.54
9:00:00 ACC 38.29
9:00:00 ACCO 11.98
9:00:00 ACET 11.54
9:00:00 ACFC 10.56
9:00:00 ACGL 91.17
9:00:00 ACGLO 24.23
9:00:00 ACGLP 23.1
9:00:00 ACHC 34.45
9:00:00 ACHN 2.78
9:00:00 ACHV 1.6
9:00:00 ACIA 35.34
9:00:00 ACIU 13.42
9:00:00 ACIW 22.96
9:00:00 ACLS 26.34
9:00:00 ACM 39.15
9:00:00 ACMR 5.26
9:00:00 ACN 160.17
9:00:00 ACNB 30.25
9:00:00 ACOR 26.55
9:00:00 ACRS 22.51
9:00:00 ACRX 1.98
9:00:00 ACST 1.15
9:00:00 ACTA 15.58
9:00:00 ACU 24.41
9:00:00 ACWI 76.17
9:00:00 ACWV 86.93
9:00:00 ACWX 52.72
9:00:00 ACXM 27.57
9:00:00 ADAP 8.97
9:00:00 ADBE 196.92
9:00:00 ADC 47.83
9:00:00 ADES 8.16
9:00:00 ADI 91.72
9:00:00 ADM 42.64
9:00:00 ADMA 3.81
9:00:00 ADMS 39.5
9:00:00 ADNT 66.25
9:00:00 ADOM 1.66
9:00:00 ADP 120.78
9:00:00 ADRA 37.37
9:00:00 ADRD 24.82
9:00:00 ADRE 47.6
9:00:00 ADRO 6.72
9:00:00 ADS 255.9
9:00:00 ADSK 114.91
9:00:00 ADT 12.12
9:00:00 ADTN 16.11
9:00:00 ADUS 36.02
9:00:00 ADVM 8.15
9:00:00 ADX 15.82
9:00:00 ADXS 3.04
9:00:00 AED 25.58
9:00:00 AEE 56.17
9:00:00 AEG 6.88
9:00:00 AEGN 25.19
9:00:00 AEH 25.56
9:00:00 AEIS 72.47
9:00:00 AEL 34.11
9:00:00 AEM 47.21
9:00:00 AEMD 1.58
9:00:00 AEO 18.29
9:00:00 AEP 68.61
9:00:00 AER 54.41
9:00:00 AERI 56.88
9:00:00 AES 11.7
9:00:00 AET 189.02
9:00:00 AETI 1.45
9:00:00 AEY 1.48
9:00:00 AEZS 2.25
9:00:00 AFAM 58.4
9:00:00 AFG 113.54
9:00:00 AFI 15.85
9:00:00 AFL 88.73
9:00:00 AFSI 13.0
9:00:00 AFSI-E 19.36
9:00:00 AFSI-F 18.58
9:00:00 AG 6.05
9:00:00 AGCO 72.83
9:00:00 AGEN 3.66
9:00:00 AGFS 7.56
9:00:00 AGG 107.95
9:00:00 AGGY 50.02
9:00:00 AGI 5.98
9:00:00 AGII 61.8
9:00:00 AGIO 80.68
9:00:00 AGLE 7.12
9:00:00 AGM 80.88
9:00:00 AGN 184.49
9:00:00 AGNC 19.07
9:00:00 AGNCN 25.21
9:00:00 AGO 35.94
9:00:00 AGQ 34.53
9:00:00 AGR 48.33
9:00:00 AGRO 9.8
9:00:00 AGRX 3.29
9:00:00 AGS 19.27
9:00:00 AGTC 5.05
9:00:00 AGYS 12.14
9:00:00 AHGP 28.64
9:00:00 AHH 14.34
9:00:00 AHL 37.76
9:00:00 AHL-C 25.87
9:00:00 AHP 9.26
9:00:00 AHT 6.46
9:00:00 AI 10.79
9:00:00 AIA 70.96
9:00:00 AIG 63.46
9:00:00 AIG+ 21.63
9:00:00 AIMC 52.82
9:00:00 AIMT 35.65
9:00:00 AINV 5.73
9:00:00 AIR 40.04
9:00:00 AIRR 27.56
9:00:00 AIT 74.48
9:00:00 AIV 41.27
9:00:00 AIZ 92.45
9:00:00 AJG 69.62
9:00:00 AJRD 27.76
9:00:00 AJX 13.53
9:00:00 AKAM 66.7
9:00:00 AKAO 12.38
9:00:00 AKBA 15.1
9:00:00 AKCA 23.41
9:00:00 AKER 0.25
9:00:00 AKO.B 28.95
9:00:00 AKR 24.43
9:00:00 AKRX 32.27
9:00:00 AKS 5.49
9:00:00 AKTS 5.77
9:00:00 AKTX 2.86
9:00:00 AL 48.86
9:00:00 ALB 111.63
9:00:00 ALBO 36.76
9:00:00 ALCO 26.9
9:00:00 ALDR 14.52
9:00:00 ALDX 7.6
9:00:00 ALE 71.85
9:00:00 ALEX 26.94
9:00:00 ALG 117.0
9:00:00 ALGN 267.58
9:00:00 ALGT 158.46
9:00:00 ALK 64.14
9:00:00 ALKS 58.04
9:00:00 ALL 98.81
9:00:00 ALL-A 24.99
9:00:00 ALL-E 25.88
9:00:00 ALL-F 25.78
9:00:00 ALLE 85.87
9:00:00 ALLT 4.95
9:00:00 ALLY 31.08
9:00:00 ALLY-A 25.94
9:00:00 ALN 0.23
9:00:00 ALNY 131.05
9:00:00 ALOG 83.55
9:00:00 ALRM 37.57
9:00:00 ALSN 44.48
9:00:00 ALT 1.86
9:00:00 ALTR 25.66
9:00:00 ALV 149.64
9:00:00 ALX 363.03
9:00:00 ALXN 123.05
9:00:00 AM 30.96
9:00:00 AMAG 14.44
9:00:00 AMAT 53.51
9:00:00 AMBA 50.39
9:00:00 AMBC 16.32
9:00:00 AMBCW 6.52
9:00:00 AMBR 7.33
9:00:00 AMC 12.58
9:00:00 AMCX 52.56
9:00:00 AMD 12.86
9:00:00 AME 76.85
9:00:00 AMED 54.16
9:00:00 AMEH 19.92
9:00:00 AMG 204.21
9:00:00 AMGN 191.54
9:00:00 AMGP 21.21
9:00:00 AMH 20.12
9:00:00 AMH-F 24.41
9:00:00 AMJ 29.21
9:00:00 AMKR 10.1
9:00:00 AMLP 11.46
9:00:00 AMMA 0.84
9:00:00 AMN 53.9
9:00:00 AMNB 37.64
9:00:00 AMOT 34.97
9:00:00 AMP 172.56
9:00:00 AMPH 19.03
9:00:00 AMRC 8.85
9:00:00 AMRK 13.51
9:00:00 AMRN 3.82
9:00:00 AMRS 4.99
9:00:00 AMSC 5.24
9:00:00 AMSF 61.04
9:00:00 AMSWA 12.77
9:00:00 AMT 145.17
9:00:00 AMTD 55.49
9:00:00 AMU 18.35
9:00:00 AMWD 135.44
9:00:00 AMX 18.55
9:00:00 AMZA 8.6
9:00:00 AMZN 1426.79
9:00:00 AN 60.97
9:00:00 ANAB 107.28
9:00:00 ANAT 126.35
9:00:00 ANDE 34.4
9:00:00 ANDV 108.98
9:00:00 ANDX 51.56
9:00:00 ANET 274.29
9:00:00 ANF 21.2
9:00:00 ANGI 13.63
9:00:00 ANGL 30.15
9:00:00 ANGO 17.21
9:00:00 ANH 4.97
9:00:00 ANIK 68.34
9:00:00 ANIP 67.71
9:00:00 ANSS 162.15
9:00:00 ANTM 243.64
9:00:00 ANY 2.34
9:00:00 AOBC 12.03
9:00:00 AOD 9.86
9:00:00 AON 141.8
9:00:00 AOS 66.66
9:00:00 AOSL 16.86
9:00:00 APA 44.63
9:00:00 APAM 39.59
9:00:00 APC 60.01
9:00:00 APD 167.72
9:00:00 APDN 1.52
9:00:00 APEN 6.17
9:00:00 APH 92.73
9:00:00 APHB 1.2
9:00:00 APLE 19.53
9:00:00 APLP 13.69
9:00:00 APLS 18.21
9:00:00 APOG 46.24
9:00:00 APOP 8.55
9:00:00 APPN 30.09
9:00:00 APPS 2.04
9:00:00 APRI 2.44
9:00:00 APRN 3.04
9:00:00 APTI 25.37
9:00:00 APTS 16.82
9:00:00 APTV 94.84
9:00:00 APU 47.19
9:00:00 APVO 3.44
9:00:00 AQ 13.37
9:00:00 AQB 2.72
9:00:00 AQMS 1.84
9:00:00 AQUA 23.2
9:00:00 AQXP 13.02
9:00:00 AR 19.49
9:00:00 ARA 19.04
9:00:00 ARAY 5.8
9:00:00 ARC 2.44
9:00:00 ARCB 35.99
9:00:00 ARCC 16.08
9:00:00 ARCH 90.9
9:00:00 ARCO 9.98
9:00:00 ARCT 8.27
9:00:00 ARD 19.93
9:00:00 ARDM 1.51
9:00:00 ARE 125.74
9:00:00 AREX 3.35
9:00:00 ARGS 2.3
9:00:00 ARGT 37.44
9:00:00 ARGX 78.24
9:00:00 ARI 18.35
9:00:00 ARII 39.36
9:00:00 ARLP 20.33
9:00:00 ARLZ 1.78
9:00:00 ARMK 45.32
9:00:00 ARMO 30.07
9:00:00 ARNA 37.33
9:00:00 ARNC 29.99
9:00:00 AROC 9.66
9:00:00 AROW 33.4
9:00:00 ARR 23.85
9:00:00 ARRS 25.24
9:00:00 ARRY 14.54
9:00:00 ARTNA 37.33
9:00:00 ARW 82.53
9:00:00 ARWR 6.11
9:00:00 ASA 11.46
9:00:00 ASB 24.99
9:00:00 ASC 7.18
9:00:00 ASCMA 9.89
9:00:00 ASGN 68.81
9:00:00 ASH 73.19
9:00:00 ASHR 33.62
9:00:00 ASIX 40.33
9:00:00 ASMB 49.68
9:00:00 ASML 200.65
9:00:00 ASNA 2.15
9:00:00 ASND 52.04
9:00:00 ASPS 30.35
9:00:00 ASRVP 27.01
9:00:00 ASTC 3.13
9:00:00 ASTE 63.11
9:00:00 ASUR 15.01
9:00:00 ASX 7.18
9:00:00 AT 2.17
9:00:00 ATEN 7.04
9:00:00 ATGE 45.88
9:00:00 ATH 50.31
9:00:00 ATHM 81.96
9:00:00 ATHN 127.94
9:00:00 ATHX 1.8
9:00:00 ATI 27.78
9:00:00 ATKR 23.91
9:00:00 ATNI 59.33
9:00:00 ATNM 0.72
9:00:00 ATNX 15.0
9:00:00 ATO 82.65
9:00:00 ATOM 4.57
9:00:00 ATOS 0.57
9:00:00 ATR 87.6
9:00:00 ATRA 38.94
9:00:00 ATRC 16.77
9:00:00 ATRI 567.08
9:00:00 ATRO 45.66
9:00:00 ATRS 2.26
9:00:00 ATSG 24.71
9:00:00 ATTO 9.72
9:00:00 ATTU 6.91
9:00:00 ATU 25.08
9:00:00 ATUS 21.87
9:00:00 ATVI 71.4
9:00:00 AU 11.1
9:00:00 AUO 4.83
9:00:00 AUPH 5.49
9:00:00 AUTO 8.3
9:00:00 AUY 3.41
9:00:00 AVA 51.01
9:00:00 AVAV 51.59
9:00:00 AVB 167.4
9:00:00 AVD 21.22
9:00:00 AVDL 11.07
9:00:00 AVEO 3.03
9:00:00 AVGO 241.81
9:00:00 AVGR 0.18
9:00:00 AVH 8.07
9:00:00 AVHI 17.32
9:00:00 AVID 5.45
9:00:00 AVIR 0.59
9:00:00 AVNW 16.71
9:00:00 AVP 2.5
9:00:00 AVT 42.96
9:00:00 AVXL 2.9
9:00:00 AVXS 121.93
9:00:00 AVY 118.15
9:00:00 AVYA 20.18
9:00:00 AWF 12.44
9:00:00 AWI 63.29
9:00:00 AWK 83.23
9:00:00 AWP 6.56
9:00:00 AWR 55.54
9:00:00 AXAS 2.36
9:00:00 AXDX 28.81
9:00:00 AXE 85.12
9:00:00 AXGN 27.4
9:00:00 AXL 18.07
9:00:00 AXON 2.05
9:00:00 AXP 98.96
9:00:00 AXS 50.61
9:00:00 AXSM 2.75
9:00:00 AXTA 31.29
9:00:00 AXTI 8.11
9:00:00 AY 21.01
9:00:00 AYI 159.33
9:00:00 AYR 23.89
9:00:00 AYTU 3.0
9:00:00 AYX 29.28
9:00:00 AZN 35.78
9:00:00 AZO 774.62
9:00:00 AZPN 78.6
9:00:00 AZRX 3.49
9:00:00 AZUL 28.81
9:00:00 AZZ 46.24
9:00:00 B 66.18
9:00:00 BA 337.58
9:00:00 BABA 199.67
9:00:00 BABY 31.3
9:00:00 BAC 31.97
9:00:00 BAC+A 20.05
9:00:00 BAC-C 26.17
9:00:00 BAC-W 26.15
9:00:00 BAH 39.51
9:00:00 BAK 31.7
9:00:00 BAL 51.22
9:00:00 BAM 41.12
9:00:00 BANC 19.75
9:00:00 BAND 23.66
9:00:00 BANF 55.48
9:00:00 BANR 54.47
9:00:00 BAP 236.45
9:00:00 BAS 19.43
9:00:00 BASI 2.1
9:00:00 BATRA 23.75
